<?xml version="1.0" ?>
<!-- =================================================================================== -->
<!-- |    This document was autogenerated by xacro from robotiq_arg2f_85_model.xacro   | -->
<!-- |    EDITING THIS FILE BY HAND IS NOT RECOMMENDED                                 | -->
<!-- =================================================================================== -->
<robot name="cubic_model">
  <link name="base_link">
    <inertial>
      <origin rpy="0 0 0" xyz="0 0 0"/>
       <mass value="0"/>
       <inertia ixx="1" ixy="0" ixz="0" iyy="1" iyz="0" izz="1"/>
    </inertial>
  </link>  

  <link name="x_base_link">
    <inertial>
      <origin rpy="0 0 0" xyz="0 0 0"/>
       <mass value="0"/>
       <inertia ixx="1" ixy="0" ixz="0" iyy="1" iyz="0" izz="1"/>
    </inertial>
  </link>  

  <link name="y_base_link">
    <inertial>
      <origin rpy="0 0 0" xyz="0 0 0"/>
       <mass value="0"/>
       <inertia ixx="1" ixy="0" ixz="0" iyy="1" iyz="0" izz="1"/>
    </inertial>
  </link>  

  <link name="z_base_link">
    <inertial>
      <origin rpy="0 0 0" xyz="0 0 0"/>
       <mass value="0"/>
       <inertia ixx="1" ixy="0" ixz="0" iyy="1" iyz="0" izz="1"/>
    </inertial>
  </link>  

  <link name="cubic_base_link">
    <inertial>
      <origin rpy="0 0 0" xyz="0 0 0"/>
       <mass value="1.2"/>
       <inertia ixx="1" ixy="0" ixz="0" iyy="1" iyz="0" izz="1"/>
    </inertial>
    <visual>
      <origin rpy="0 0 0" xyz="0 0 0"/>
      <geometry>
        <box size="0.022 0.03 0.05"/>
      </geometry>
      <material name="Light09">
        <color rgba="0.9 0.9 0.9 1"/>
      </material>
    </visual>
    <collision>
      <origin rpy="0 0 0" xyz="0 0 0"/>
      <geometry>
        <box size="0.022 0.03 0.05"/>
      </geometry>
    </collision>
  </link>  

  <joint name="base_to_x" type="prismatic">
    <origin rpy="0 0 0" xyz="0 0 0"/>
    <parent link="base_link"/>
    <child link="x_base_link"/>
    <axis xyz="1 0 0"/>
    <limit effort="1000" lower="-1" upper="1" velocity="2.0"/>
  </joint>

  <joint name="x_to_y" type="prismatic">
    <origin rpy="0 0 0" xyz="0 0 0"/>
    <parent link="x_base_link"/>
    <child link="y_base_link"/>
    <axis xyz="0 1 0"/>
    <limit effort="1000" lower="-1" upper="1" velocity="2.0"/>
  </joint>

  <joint name="y_to_z" type="prismatic">
    <origin rpy="0 0 0" xyz="0 0 0"/>
    <parent link="y_base_link"/>
    <child link="z_base_link"/>
    <axis xyz="0 0 1"/>
    <limit effort="1000" lower="-2" upper="2" velocity="2.0"/>
  </joint>

  <joint name="z_to_rot" type="revolute">
    <origin rpy="0 0 0" xyz="0 0 0"/>
    <parent link="z_base_link"/>
    <child link="cubic_base_link"/>
    <axis xyz="0 0 1"/>
    <limit effort="1000" lower="-3.14" upper="3.14" velocity="2.0"/>
  </joint>

  <!-- <link name="dummy_center_indicator_link">
    <visual>
      <geometry>
        <box size="0.025 0.122 0.002"/>
      </geometry>
      <material name="Dark4">
        <color rgba="0.4 0.4 0.4 1"/>
      </material>
    </visual>
    <inertial>
      <mass value="0.1" />
      <inertia ixx = "0" ixy = "0" ixz = "0"
               iyx = "0" iyy = "0" iyz = "0"
               izx = "0" izy = "0" izz = "0" />
    </inertial>
  </link>
  <joint name="dummy_center_fixed_joint" type="fixed">
    <parent link="z_base_link"/>
    <child link="dummy_center_indicator_link"/>
    <origin xyz="0 0 -0.013"/>
  </joint> -->

</robot>
